2019-11-25 14:59:18,880 ERROR: Exception on /edit_profile [POST] [in c:\users\duvolle\downloads\opendatascience\ods\lib\site-packages\flask\app.py:1891]
Traceback (most recent call last):
  File "c:\users\duvolle\downloads\opendatascience\ods\lib\site-packages\sqlalchemy\engine\base.py", line 1249, in _execute_context
    cursor, statement, parameters, context
  File "c:\users\duvolle\downloads\opendatascience\ods\lib\site-packages\sqlalchemy\engine\default.py", line 580, in do_execute
    cursor.execute(statement, parameters)
sqlite3.IntegrityError: UNIQUE constraint failed: user.username

The above exception was the direct cause of the following exception:

Traceback (most recent call last):
  File "c:\users\duvolle\downloads\opendatascience\ods\lib\site-packages\flask\app.py", line 2446, in wsgi_app
    response = self.full_dispatch_request()
  File "c:\users\duvolle\downloads\opendatascience\ods\lib\site-packages\flask\app.py", line 1951, in full_dispatch_request
    rv = self.handle_user_exception(e)
  File "c:\users\duvolle\downloads\opendatascience\ods\lib\site-packages\flask\app.py", line 1820, in handle_user_exception
    reraise(exc_type, exc_value, tb)
  File "c:\users\duvolle\downloads\opendatascience\ods\lib\site-packages\flask\_compat.py", line 39, in reraise
    raise value
  File "c:\users\duvolle\downloads\opendatascience\ods\lib\site-packages\flask\app.py", line 1949, in full_dispatch_request
    rv = self.dispatch_request()
  File "c:\users\duvolle\downloads\opendatascience\ods\lib\site-packages\flask\app.py", line 1935, in dispatch_request
    return self.view_functions[rule.endpoint](**req.view_args)
  File "c:\users\duvolle\downloads\opendatascience\ods\lib\site-packages\flask_login\utils.py", line 261, in decorated_view
    return func(*args, **kwargs)
  File "C:\Users\duvolle\Desktop\microblog\app\routes.py", line 89, in edit_profile
    db.session.commit()
  File "c:\users\duvolle\downloads\opendatascience\ods\lib\site-packages\sqlalchemy\orm\scoping.py", line 162, in do
    return getattr(self.registry(), name)(*args, **kwargs)
  File "c:\users\duvolle\downloads\opendatascience\ods\lib\site-packages\sqlalchemy\orm\session.py", line 1027, in commit
    self.transaction.commit()
  File "c:\users\duvolle\downloads\opendatascience\ods\lib\site-packages\sqlalchemy\orm\session.py", line 494, in commit
    self._prepare_impl()
  File "c:\users\duvolle\downloads\opendatascience\ods\lib\site-packages\sqlalchemy\orm\session.py", line 473, in _prepare_impl
    self.session.flush()
  File "c:\users\duvolle\downloads\opendatascience\ods\lib\site-packages\sqlalchemy\orm\session.py", line 2470, in flush
    self._flush(objects)
  File "c:\users\duvolle\downloads\opendatascience\ods\lib\site-packages\sqlalchemy\orm\session.py", line 2608, in _flush
    transaction.rollback(_capture_exception=True)
  File "c:\users\duvolle\downloads\opendatascience\ods\lib\site-packages\sqlalchemy\util\langhelpers.py", line 68, in __exit__
    compat.reraise(exc_type, exc_value, exc_tb)
  File "c:\users\duvolle\downloads\opendatascience\ods\lib\site-packages\sqlalchemy\util\compat.py", line 153, in reraise
    raise value
  File "c:\users\duvolle\downloads\opendatascience\ods\lib\site-packages\sqlalchemy\orm\session.py", line 2568, in _flush
    flush_context.execute()
  File "c:\users\duvolle\downloads\opendatascience\ods\lib\site-packages\sqlalchemy\orm\unitofwork.py", line 422, in execute
    rec.execute(self)
  File "c:\users\duvolle\downloads\opendatascience\ods\lib\site-packages\sqlalchemy\orm\unitofwork.py", line 589, in execute
    uow,
  File "c:\users\duvolle\downloads\opendatascience\ods\lib\site-packages\sqlalchemy\orm\persistence.py", line 236, in save_obj
    update,
  File "c:\users\duvolle\downloads\opendatascience\ods\lib\site-packages\sqlalchemy\orm\persistence.py", line 996, in _emit_update_statements
    statement, multiparams
  File "c:\users\duvolle\downloads\opendatascience\ods\lib\site-packages\sqlalchemy\engine\base.py", line 988, in execute
    return meth(self, multiparams, params)
  File "c:\users\duvolle\downloads\opendatascience\ods\lib\site-packages\sqlalchemy\sql\elements.py", line 287, in _execute_on_connection
    return connection._execute_clauseelement(self, multiparams, params)
  File "c:\users\duvolle\downloads\opendatascience\ods\lib\site-packages\sqlalchemy\engine\base.py", line 1107, in _execute_clauseelement
    distilled_params,
  File "c:\users\duvolle\downloads\opendatascience\ods\lib\site-packages\sqlalchemy\engine\base.py", line 1253, in _execute_context
    e, statement, parameters, cursor, context
  File "c:\users\duvolle\downloads\opendatascience\ods\lib\site-packages\sqlalchemy\engine\base.py", line 1473, in _handle_dbapi_exception
    util.raise_from_cause(sqlalchemy_exception, exc_info)
  File "c:\users\duvolle\downloads\opendatascience\ods\lib\site-packages\sqlalchemy\util\compat.py", line 398, in raise_from_cause
    reraise(type(exception), exception, tb=exc_tb, cause=cause)
  File "c:\users\duvolle\downloads\opendatascience\ods\lib\site-packages\sqlalchemy\util\compat.py", line 152, in reraise
    raise value.with_traceback(tb)
  File "c:\users\duvolle\downloads\opendatascience\ods\lib\site-packages\sqlalchemy\engine\base.py", line 1249, in _execute_context
    cursor, statement, parameters, context
  File "c:\users\duvolle\downloads\opendatascience\ods\lib\site-packages\sqlalchemy\engine\default.py", line 580, in do_execute
    cursor.execute(statement, parameters)
sqlalchemy.exc.IntegrityError: (sqlite3.IntegrityError) UNIQUE constraint failed: user.username
[SQL: UPDATE user SET username=?, about_me=? WHERE user.id = ?]
[parameters: ('john', '', 3)]
(Background on this error at: http://sqlalche.me/e/gkpj)
2019-11-30 14:47:36,351 INFO: Microblog startup [in C:\Users\duvolle\Desktop\microblog\app\__init__.py:45]
2019-11-30 14:48:02,751 INFO: Microblog startup [in C:\Users\duvolle\Desktop\microblog\app\__init__.py:45]
2019-12-02 14:16:42,208 INFO: Microblog startup [in C:\Users\duvolle\Desktop\microblog\app\__init__.py:45]
2019-12-03 13:37:50,484 INFO: Microblog startup [in C:\Users\duvolle\Desktop\microblog\app\__init__.py:45]
2019-12-03 14:27:11,492 INFO: Microblog startup [in C:\Users\duvolle\Desktop\microblog\app\__init__.py:45]
2019-12-03 14:30:17,749 INFO: Microblog startup [in C:\Users\duvolle\Desktop\microblog\app\__init__.py:45]
2019-12-04 14:02:16,056 INFO: Microblog startup [in C:\Users\duvolle\Desktop\microblog\app\__init__.py:45]
2019-12-05 14:50:32,110 INFO: Microblog startup [in C:\Users\duvolle\Desktop\microblog\app\__init__.py:45]
2019-12-06 11:55:31,881 INFO: Microblog startup [in C:\Users\duvolle\Desktop\microblog\app\__init__.py:45]
2019-12-06 12:22:09,127 INFO: Microblog startup [in C:\Users\duvolle\Desktop\microblog\app\__init__.py:45]
2019-12-07 14:06:14,729 INFO: Microblog startup [in C:\Users\duvolle\Desktop\microblog\app\__init__.py:47]
2019-12-07 14:25:37,098 INFO: Microblog startup [in C:\Users\duvolle\Desktop\microblog\app\__init__.py:47]
2019-12-11 12:50:06,574 INFO: Microblog startup [in C:\Users\duvolle\Desktop\microblog\app\__init__.py:47]
2019-12-11 12:52:06,190 ERROR: Exception on /reset_password/eyJ0eXAiOiJKV1QiLCJhbGciOiJIUzI1NiJ9.eyJyZXNldF9wYXNzd29yZCI6NSwiZXhwIjoxNTc2MDU4NDkxLjQ3Mzk1Njh9.2n6bs91Qtw4KeqmOVV2IdS997mPAGhDWNS4rKTB6AS8 [GET] [in c:\users\duvolle\downloads\opendatascience\ods\lib\site-packages\flask\app.py:1891]
Traceback (most recent call last):
  File "c:\users\duvolle\downloads\opendatascience\ods\lib\site-packages\flask\app.py", line 2446, in wsgi_app
    response = self.full_dispatch_request()
  File "c:\users\duvolle\downloads\opendatascience\ods\lib\site-packages\flask\app.py", line 1951, in full_dispatch_request
    rv = self.handle_user_exception(e)
  File "c:\users\duvolle\downloads\opendatascience\ods\lib\site-packages\flask\app.py", line 1820, in handle_user_exception
    reraise(exc_type, exc_value, tb)
  File "c:\users\duvolle\downloads\opendatascience\ods\lib\site-packages\flask\_compat.py", line 39, in reraise
    raise value
  File "c:\users\duvolle\downloads\opendatascience\ods\lib\site-packages\flask\app.py", line 1949, in full_dispatch_request
    rv = self.dispatch_request()
  File "c:\users\duvolle\downloads\opendatascience\ods\lib\site-packages\flask\app.py", line 1935, in dispatch_request
    return self.view_functions[rule.endpoint](**req.view_args)
  File "C:\Users\duvolle\Desktop\microblog\app\routes.py", line 94, in reset_password
    form = ResetPasswordForm()
NameError: name 'ResetPasswordForm' is not defined
2019-12-11 12:58:37,448 ERROR: Exception on /reset_password/eyJ0eXAiOiJKV1QiLCJhbGciOiJIUzI1NiJ9.eyJyZXNldF9wYXNzd29yZCI6NSwiZXhwIjoxNTc2MDU4ODk3LjQ5MTA2MjJ9.yhnLZNbh-GsPi2m-6sNmxJNFQSYmgk-LwOumjdCHoqQ [GET] [in c:\users\duvolle\downloads\opendatascience\ods\lib\site-packages\flask\app.py:1891]
Traceback (most recent call last):
  File "c:\users\duvolle\downloads\opendatascience\ods\lib\site-packages\flask\app.py", line 2446, in wsgi_app
    response = self.full_dispatch_request()
  File "c:\users\duvolle\downloads\opendatascience\ods\lib\site-packages\flask\app.py", line 1951, in full_dispatch_request
    rv = self.handle_user_exception(e)
  File "c:\users\duvolle\downloads\opendatascience\ods\lib\site-packages\flask\app.py", line 1820, in handle_user_exception
    reraise(exc_type, exc_value, tb)
  File "c:\users\duvolle\downloads\opendatascience\ods\lib\site-packages\flask\_compat.py", line 39, in reraise
    raise value
  File "c:\users\duvolle\downloads\opendatascience\ods\lib\site-packages\flask\app.py", line 1949, in full_dispatch_request
    rv = self.dispatch_request()
  File "c:\users\duvolle\downloads\opendatascience\ods\lib\site-packages\flask\app.py", line 1935, in dispatch_request
    return self.view_functions[rule.endpoint](**req.view_args)
  File "C:\Users\duvolle\Desktop\microblog\app\routes.py", line 94, in reset_password
    return redirect(url_for('index'))
NameError: name 'ResetPasswordForm' is not defined
